<?xml version="1.0" encoding="utf-8"?>
<!-- This URDF was automatically created by SolidWorks to URDF Exporter! Originally created by Stephen Brawner (brawner@gmail.com) 
     Commit Version: 1.6.0-1-g15f4949  Build Version: 1.6.7594.29634
     For more information, please see http://wiki.ros.org/sw_urdf_exporter -->
<robot
  name="scara_arm_dual">
  <link name="world">
    <pose> 0 0 0 0 0 0</pose>
  </link>
  <joint name="world_fixed" type="fixed">
    <!-- Raise slightly above ground to fix low real-time factor...
          most likely due to tip of Link 1 intersecting ground plane -->
    <origin
      xyz="0.0 0.0 0.01" 
      rpy="0 0 0" />
    <parent link="world"/>
    <child link="base_link"/>
  </joint>
  <link
    name="base_link">
    <inertial>
      <origin
        xyz="-1.3323E-15 0.001416 0.028579"
        rpy="0 0 0" />
      <mass
        value="1.8167" />
      <inertia
        ixx="0.0092008"
        ixy="4.2883E-17"
        ixz="1.8255E-17"
        iyy="0.0050311"
        iyz="-4.9106E-05"
        izz="0.010824" />
    </inertial>
    <visual>
      <origin
        xyz="0 0 0"
        rpy="0 0 0" />
      <geometry>
        <mesh
          filename="model://arm_base_link.STL" />
      </geometry>
      <material
        name="">
        <color
          rgba="0.79216 0.81961 0.93333 1" />
      </material>
    </visual>
    <collision>
      <origin
        xyz="0 0 0"
        rpy="0 0 0" />
      <geometry>
        <mesh
          filename="model://arm_base_link.STL" />
      </geometry>
    </collision>
  </link>
  <link
    name="z_link">
    <inertial>
      <origin
        xyz="0.00052515 6.5815E-15 0.0054279"
        rpy="0 0 0" />
      <mass
        value="0.061611" />
      <inertia
        ixx="9.8218E-05"
        ixy="9.7777E-19"
        ixz="-4.4627E-07"
        iyy="1.1718E-05"
        iyz="-1.3574E-18"
        izz="0.00010811" />
    </inertial>
    <visual>
      <origin
        xyz="0 0 0"
        rpy="0 0 0" />
      <geometry>
        <mesh
          filename="model://z_link.STL" />
      </geometry>
      <material
        name="">
        <color
          rgba="0.79216 0.81961 0.93333 1" />
      </material>
    </visual>
    <collision>
      <origin
        xyz="0 0 0"
        rpy="0 0 0" />
      <geometry>
        <mesh
          filename="model://z_link.STL" />
      </geometry>
    </collision>
  </link>
  <joint
    name="z_prism"
    type="prismatic">
    <origin
      xyz="0.00097648 0 0.060561"
      rpy="0 0 0" />
    <parent
      link="base_link" />
    <child
      link="z_link" />
    <axis
      xyz="0 0 1" />
    <limit
      lower="0.01"
      upper="0.27"
      effort="100"
      velocity="100" />
  </joint>
  <link
    name="right_shldr_link">
    <inertial>
      <origin
        xyz="0.052774 0.0011402 -0.0081027"
        rpy="0 0 0" />
      <mass
        value="0.025561" />
      <inertia
        ixx="1.2589E-06"
        ixy="1.5186E-06"
        ixz="2.2459E-07"
        iyy="3.4818E-05"
        iyz="4.9752E-09"
        izz="3.495E-05" />
    </inertial>
    <visual>
      <origin
        xyz="0 0 0"
        rpy="0 0 0" />
      <geometry>
        <mesh
          filename="model://right_shldr_link.STL" />
      </geometry>
      <material
        name="">
        <color
          rgba="0.96471 0.96471 0.95294 1" />
      </material>
    </visual>
    <collision>
      <origin
        xyz="0 0 0"
        rpy="0 0 0" />
      <geometry>
        <mesh
          filename="model://right_shldr_link.STL" />
      </geometry>
    </collision>
  </link>
  <joint
    name="right_shldr_rev"
    type="revolute">
    <origin
      xyz="0.017454 -0.055 0.028419"
      rpy="0 0 -0.61584" />
    <parent
      link="z_link" />
    <child
      link="right_shldr_link" />
    <axis
      xyz="0 0 -1" />
    <limit
      lower="-1.0"
      upper="1.0"
      effort="100"
      velocity="100" />
  </joint>
  <link
    name="right_elbw_link">
    <inertial>
      <origin
        xyz="0.10936 0.0025108 -0.015181"
        rpy="0 0 0" />
      <mass
        value="0.052137" />
      <inertia
        ixx="1.8081E-05"
        ixy="-6.9009E-06"
        ixz="2.9597E-05"
        iyy="0.00019669"
        iyz="2.6836E-06"
        izz="0.00018284" />
    </inertial>
    <visual>
      <origin
        xyz="0 0 0"
        rpy="0 0 0" />
      <geometry>
        <mesh
          filename="model://right_elbw_link.STL" />
      </geometry>
      <material
        name="">
        <color
          rgba="0.96471 0.96471 0.95294 1" />
      </material>
    </visual>
    <collision>
      <origin
        xyz="0 0 0"
        rpy="0 0 0" />
      <geometry>
        <mesh
          filename="model://right_elbw_link.STL" />
      </geometry>
    </collision>
  </link>
  <joint
    name="right_elbw_rev"
    type="revolute">
    <origin
      xyz="0.1 0 -0.018419"
      rpy="0 0 1.4276" />
    <parent
      link="right_shldr_link" />
    <child
      link="right_elbw_link" />
    <axis
      xyz="0 0 -1" />
    <limit
      lower="0.1"
      upper="1.75"
      effort="100"
      velocity="100" />
  </joint>
  <link
    name="EE_link">
    <inertial>
      <origin
        xyz="-7.1124E-15 4.8087E-15 0.030953"
        rpy="0 0 0" />
      <mass
        value="0.0062757" />
      <inertia
        ixx="1.5736E-06"
        ixy="7.714E-35"
        ixz="7.8936E-23"
        iyy="1.5736E-06"
        iyz="2.6001E-22"
        izz="1.1427E-07" />
    </inertial>
    <visual>
      <origin
        xyz="0 0 0"
        rpy="0 0 0" />
      <geometry>
        <mesh
          filename="model://EE_link.STL" />
      </geometry>
      <material
        name="">
        <color
          rgba="0.79216 0.81961 0.93333 1" />
      </material>
    </visual>
    <collision>
      <origin
        xyz="0 0 0"
        rpy="0 0 0" />
      <geometry>
        <mesh
          filename="model://EE_link.STL" />
      </geometry>
    </collision>
  </link>
  <joint
    name="EE_fixed"
    type="fixed">
    <origin
      xyz="0.1618 0 -0.07008"
      rpy="0 0 0" />
    <parent
      link="right_elbw_link" />
    <child
      link="EE_link" />
    <axis
      xyz="0 0 0" />
  </joint>
  <link
    name="left_shldr_link">
    <inertial>
      <origin
        xyz="0.052774 -0.0011402 -0.0081027"
        rpy="0 0 0" />
      <mass
        value="0.025561" />
      <inertia
        ixx="1.2589E-06"
        ixy="-1.5186E-06"
        ixz="2.2458E-07"
        iyy="3.4818E-05"
        iyz="-4.9734E-09"
        izz="3.495E-05" />
    </inertial>
    <visual>
      <origin
        xyz="0 0 0"
        rpy="0 0 0" />
      <geometry>
        <mesh
          filename="model://left_shldr_link.STL" />
      </geometry>
      <material
        name="">
        <color
          rgba="0.96471 0.96471 0.95294 1" />
      </material>
    </visual>
    <collision>
      <origin
        xyz="0 0 0"
        rpy="0 0 0" />
      <geometry>
        <mesh
          filename="model://left_shldr_link.STL" />
      </geometry>
    </collision>
  </link>
  <joint
    name="left_shldr_rev"
    type="revolute">
    <origin
      xyz="0.017454 0.055 0.028419"
      rpy="0 0 0.68233" />
    <parent
      link="z_link" />
    <child
      link="left_shldr_link" />
    <axis
      xyz="0 0 1" />
    <limit
      lower="-1.0"
      upper="1.0"
      effort="100"
      velocity="100" />
  </joint>
  <link
    name="left_elbw_link">
    <inertial>
      <origin
        xyz="0.077901 1.6504E-05 0.00080553"
        rpy="0 0 0" />
      <mass
        value="0.034948" />
      <inertia
        ixx="3.0317E-06"
        ixy="1.8828E-08"
        ixz="-1.1211E-05"
        iyy="0.0001049"
        iyz="6.3038E-08"
        izz="0.00010418" />
    </inertial>
    <visual>
      <origin
        xyz="0 0 0"
        rpy="0 0 0" />
      <geometry>
        <mesh
          filename="model://left_elbw_link.STL" />
      </geometry>
      <material
        name="">
        <color
          rgba="0.96471 0.96471 0.95294 1" />
      </material>
    </visual>
    <collision>
      <origin
        xyz="0 0 0"
        rpy="0 0 0" />
      <geometry>
        <mesh
          filename="model://left_elbw_link.STL" />
      </geometry>
    </collision>
  </link>
  <joint
    name="left_elbw_rev"
    type="revolute">
    <origin
      xyz="0.1 0 -0.018419"
      rpy="0 0 -1.4593" />
    <parent
      link="left_shldr_link" />
    <child
      link="left_elbw_link" />
    <axis
      xyz="0 0 1" />
    <limit
      lower="0.1"
      upper="1.75"
      effort="100"
      velocity="100" />
  </joint>
  <link
    name="dummy_link">
    <inertial>
      <origin
        xyz="-7.1193E-15 4.8087E-15 0.030953"
        rpy="0 0 0" />
      <mass
        value="0.0062757" />
      <inertia
        ixx="1.5736E-06"
        ixy="7.7136E-35"
        ixz="7.8936E-23"
        iyy="1.5736E-06"
        iyz="2.6001E-22"
        izz="1.1427E-07" />
    </inertial>
    <visual>
      <origin
        xyz="0 0 0"
        rpy="0 0 0" />
      <geometry>
        <mesh
          filename="model://dummy_link.STL" />
      </geometry>
      <material
        name="">
        <color
          rgba="0.79216 0.81961 0.93333 1" />
      </material>
    </visual>
    <collision>
      <origin
        xyz="0 0 0"
        rpy="0 0 0" />
      <geometry>
        <mesh
          filename="model://dummy_link.STL" />
      </geometry>
    </collision>
  </link>
  <joint
    name="dummy_rev"
    type="fixed">
    <origin
      xyz="0.1618 0 -0.07008"
      rpy="0 0 1.5887" />
    <parent
      link="left_elbw_link" />
    <child
      link="dummy_link" />
    <axis
      xyz="0 0 0" />
    <limit
      lower="0"
      upper="6.28"
      effort="0"
      velocity="0" />
  </joint>

  <ros2_control name="GazeboSystem" type="system">
    <hardware>
      <plugin>gazebo_ros2_control/GazeboSystem</plugin>
    </hardware>

    <!-- <joint name="z_prism">
      <command_interface name="position">
        <param name="min">"-1000"</param>
        <param name="max">"1000"</param>
      </command_interface>
      <state_interface name="position"/>
      <state_interface name="velocity"/>
      <state_interface name="effort"/>
    </joint> -->

    <joint name="right_shldr_rev">
      <command_interface name="position">
        <param name="min">"-1000"</param>
        <param name="max">"1000"</param>
      </command_interface>
      <state_interface name="position"/>
      <state_interface name="velocity"/>
      <state_interface name="effort"/>
    </joint>

    <joint name="right_elbw_rev">
      <command_interface name="position">
        <param name="min">"-1000"</param>
        <param name="max">"1000"</param>
      </command_interface>
      <state_interface name="position"/>
      <state_interface name="velocity"/>
      <state_interface name="effort"/>
    </joint>
<!-- 
  <joint name="left_shldr_rev">
      <command_interface name="position">
        <param name="min">"-1000"</param>
        <param name="max">"1000"</param>
      </command_interface>
      <state_interface name="position"/>
      <state_interface name="velocity"/>
      <state_interface name="effort"/>
    </joint>

    <joint name="left_elbw_rev">
      <command_interface name="position">
        <param name="min">"-1000"</param>
        <param name="max">"1000"</param>
      </command_interface>
      <state_interface name="position"/>
      <state_interface name="velocity"/>
      <state_interface name="effort"/>
    </joint> -->
  </ros2_control>

  <gazebo>
    <plugin name="gazebo_ros2_control" filename="libgazebo_ros2_control.so">
     <robot_param>robot_description</robot_param>
      <robot_param_node>robot_state_publisher</robot_param_node>
      <parameters>$(find simple_arm)/config/joint_names_Simple_arm.yaml</parameters>
    </plugin>
  
    <plugin name="gazebo_ros_p3d" filename="libgazebo_ros_p3d.so">
      <ros>
        <namespace>/simple_arm</namespace>
        <argument>odom:=gazebo_odom</argument>
      </ros>

      
      <body_name>base_link</body_name>
      <frame_name>world</frame_name>
      <update_rate>50</update_rate> 
      <xyz_offset>0 0 0</xyz_offset>
      <rpy_offset>0 0 0</rpy_offset>
      <gaussian_noise>0.0001</gaussian_noise>

    </plugin>
  </gazebo>

</robot>
