<?xml version="1.0" encoding="utf-8"?>

<robot
  name="Simple_arm">
  <link
    name="base_link">
    <inertial>
      <origin
        xyz="0 0.00096032 -0.077662"
        rpy="0 0 0" />
      <mass
        value="2.2832" />
      <inertia
        ixx="0.0060931"
        ixy="6.8625E-19"
        ixz="-2.0657E-17"
        iyy="0.013622"
        iyz="-1.0005E-18"
        izz="0.015978" />
    </inertial>
    <visual>
      <origin
        xyz="0 0 0"
        rpy="0 0 0" />
      <geometry>
        <mesh
          filename="model://arm_base_link.STL" />
      </geometry>
      <material
        name="">
        <color
          rgba="0.79216 0.81961 0.93333 1" />
      </material>
    </visual>
    <collision>
      <origin
        xyz="0 0 0"
        rpy="0 0 0" />
      <geometry>
        <mesh
          filename="model://arm_base_link.STL" />
      </geometry>
    </collision>
  </link>
  <link
    name="z_link">
    <inertial>
      <origin
        xyz="6.7446E-15 -0.00054131 0.0054279"
        rpy="0 0 0" />
      <mass
        value="0.061611" />
      <inertia
        ixx="1.1718E-05"
        ixy="-1.9639E-20"
        ixz="1.3001E-21"
        iyy="9.8218E-05"
        iyz="4.4627E-07"
        izz="0.00010811" />
    </inertial>
    <visual>
      <origin
        xyz="0 0 0"
        rpy="0 0 0" />
      <geometry>
        <mesh
          filename="model://z_link.STL" />
      </geometry>
      <material
        name="">
        <color
          rgba="0.79216 0.81961 0.93333 1" />
      </material>
    </visual>
    <collision>
      <origin
        xyz="0 0 0"
        rpy="0 0 0" />
      <geometry>
        <mesh
          filename="model://z_link.STL" />
      </geometry>
    </collision>
  </link>
  <joint
    name="z_pris"
    type="prismatic">
    <origin
      xyz="0 0 -0.05"
      rpy="0 0 0" />
    <parent
      link="base_link" />
    <child
      link="z_link" />
    <axis
      xyz="0 0 1" />
    <limit
      lower="0"
      upper="290"
      effort="0"
      velocity="0" />
  </joint>
  <link
    name="right_shldr_link">
    <inertial>
      <origin
        xyz="-0.016836 -0.05003 -0.039684"
        rpy="0 0 0" />
      <mass
        value="0.025561" />
      <inertia
        ixx="2.9984E-05"
        ixy="-1.1881E-05"
        ixz="-7.1531E-08"
        iyy="6.0928E-06"
        iyz="-2.1295E-07"
        izz="3.495E-05" />
    </inertial>
    <visual>
      <origin
        xyz="0 0 0"
        rpy="0 0 0" />
      <geometry>
        <mesh
          filename="model://right_shldr_link.STL" />
      </geometry>
      <material
        name="">
        <color
          rgba="0.96471 0.96471 0.95294 1" />
      </material>
    </visual>
    <collision>
      <origin
        xyz="0 0 0"
        rpy="0 0 0" />
      <geometry>
        <mesh
          filename="model://right_shldr_link.STL" />
      </geometry>
    </collision>
  </link>
  <joint
    name="right_shldr_rev"
    type="revolute">
    <origin
      xyz="-0.055 -0.01747 0.06"
      rpy="0 0 0" />
    <parent
      link="z_link" />
    <child
      link="right_shldr_link" />
    <axis
      xyz="0 0 1" />
    <limit
      lower="0"
      upper="0"
      effort="0"
      velocity="0" />
  </joint>
  <link
    name="right_elbw_link">
    <inertial>
      <origin
        xyz="0.10495 -0.030838 -0.034081"
        rpy="0 0 0" />
      <mass
        value="0.052137" />
      <inertia
        ixx="3.0576E-05"
        ixy="4.6078E-05"
        ixz="2.9013E-05"
        iyy="0.00018419"
        iyz="-6.4366E-06"
        izz="0.00018284" />
    </inertial>
    <visual>
      <origin
        xyz="0 0 0"
        rpy="0 0 0" />
      <geometry>
        <mesh
          filename="model://right_elbw_link.STL" />
      </geometry>
      <material
        name="">
        <color
          rgba="0.96471 0.96471 0.95294 1" />
      </material>
    </visual>
    <collision>
      <origin
        xyz="0 0 0"
        rpy="0 0 0" />
      <geometry>
        <mesh
          filename="model://right_elbw_link.STL" />
      </geometry>
    </collision>
  </link>
  <joint
    name="right_elbw_rev"
    type="revolute">
    <origin
      xyz="-0.033934 -0.094066 -0.0311"
      rpy="0 0 -0.34621" />
    <parent
      link="right_shldr_link" />
    <child
      link="right_elbw_link" />
    <axis
      xyz="0 0 -1" />
    <limit
      lower="0"
      upper="0"
      effort="0"
      velocity="0" />
  </joint>
  <link
    name="left_shldr_link">
    <inertial>
      <origin
        xyz="0.040977 -0.033277 -0.039684"
        rpy="0 0 0" />
      <mass
        value="0.025561" />
      <inertia
        ixx="1.2418E-05"
        ixy="1.5883E-05"
        ixz="1.743E-07"
        iyy="2.3659E-05"
        iyz="-1.417E-07"
        izz="3.495E-05" />
    </inertial>
    <visual>
      <origin
        xyz="0 0 0"
        rpy="0 0 0" />
      <geometry>
        <mesh
          filename="model://left_shldr_link.STL" />
      </geometry>
      <material
        name="">
        <color
          rgba="0.96471 0.96471 0.95294 1" />
      </material>
    </visual>
    <collision>
      <origin
        xyz="0 0 0"
        rpy="0 0 0" />
      <geometry>
        <mesh
          filename="model://left_shldr_link.STL" />
      </geometry>
    </collision>
  </link>
  <joint
    name="left_shldr_rev"
    type="revolute">
    <origin
      xyz="0.055 -0.01747 0.06"
      rpy="0 0 0" />
    <parent
      link="z_link" />
    <child
      link="left_shldr_link" />
    <axis
      xyz="0 0 1" />
    <limit
      lower="0"
      upper="0"
      effort="0"
      velocity="0" />
  </joint>
  <link
    name="left_elbw_link">
    <inertial>
      <origin
        xyz="-0.07785 -0.0028281 -0.018094"
        rpy="0 0 0" />
      <mass
        value="0.034948" />
      <inertia
        ixx="3.163E-06"
        ixy="-3.6554E-06"
        ixz="1.1206E-05"
        iyy="0.00010476"
        iyz="3.4164E-07"
        izz="0.00010418" />
    </inertial>
    <visual>
      <origin
        xyz="0 0 0"
        rpy="0 0 0" />
      <geometry>
        <mesh
          filename="model://left_elbw_link.STL" />
      </geometry>
      <material
        name="">
        <color
          rgba="0.96471 0.96471 0.95294 1" />
      </material>
    </visual>
    <collision>
      <origin
        xyz="0 0 0"
        rpy="0 0 0" />
      <geometry>
        <mesh
          filename="model://left_elbw_link.STL" />
      </geometry>
    </collision>
  </link>
  <joint
    name="left_elbw_rev"
    type="revolute">
    <origin
      xyz="0.078971 -0.061348 -0.0311"
      rpy="0 0 0.91033" />
    <parent
      link="left_shldr_link" />
    <child
      link="left_elbw_link" />
    <axis
      xyz="0 0 1" />
    <limit
      lower="0"
      upper="0"
      effort="0"
      velocity="0" />
  </joint>
  <ros2_control name="GazeboSystem" type="system">
    <hardware>
      <plugin>gazebo_ros2_control/GazeboSystem</plugin>
    </hardware>

    <joint name="z_pris">
      <command_interface name="position">
        <param name="min">"-1000"</param>
        <param name="max">"1000"</param>
      </command_interface>
      <state_interface name="position"/>
      <state_interface name="velocity"/>
      <state_interface name="effort"/>
    </joint>

    <joint name="right_shldr_rev">
      <command_interface name="position">
        <param name="min">"-1000"</param>
        <param name="max">"1000"</param>
      </command_interface>
      <state_interface name="position"/>
      <state_interface name="velocity"/>
      <state_interface name="effort"/>
    </joint>

    <joint name="right_elbw_rev">
      <command_interface name="position">
        <param name="min">"-1000"</param>
        <param name="max">"1000"</param>
      </command_interface>
      <state_interface name="position"/>
      <state_interface name="velocity"/>
      <state_interface name="effort"/>
    </joint>

    <joint name="left_shldr_rev">
      <command_interface name="position">
        <param name="min">"-1000"</param>
        <param name="max">"1000"</param>
      </command_interface>
      <state_interface name="position"/>
      <state_interface name="velocity"/>
      <state_interface name="effort"/>
    </joint>

    <joint name="left_elbw_rev">
      <command_interface name="position">
        <param name="min">"-1000"</param>
        <param name="max">"1000"</param>
      </command_interface>
      <state_interface name="position"/>
      <state_interface name="velocity"/>
      <state_interface name="effort"/>
    </joint>
  </ros2_control>

  <gazebo>
    <plugin name="gazebo_ros2_control" filename="libgazebo_ros2_control.so">
     <robot_param>robot_description</robot_param>
      <robot_param_node>robot_state_publisher</robot_param_node>
     <parameters>$(find simple_arm)/config/joint_names_Simple_arm.yaml</parameters>
    </plugin>
    <!-- 3D Pose publisher (emulate motion capture) -->
    <!-- See: https://github.com/ros-simulation/gazebo_ros_pkgs/wiki/ROS-2-Migration:-P3D -->
    <plugin name="gazebo_ros_p3d" filename="libgazebo_ros_p3d.so">
      <ros>
        <!-- Add namespace and remap the default topic -->
        <namespace>/simple_arm</namespace>
        <argument>odom:=gazebo_odom</argument>
      </ros>

      <!-- Replace camelCase elements with camel_case ones -->
      <body_name>base_link</body_name>
      <frame_name>world</frame_name>
      <update_rate>50</update_rate> <!-- If set to 0, or don't include, will default to max possible -->
      <xyz_offset>0 0 0</xyz_offset>
      <rpy_offset>0 0 0</rpy_offset>
      <gaussian_noise>0.0001</gaussian_noise>

    </plugin>
  </gazebo>


</robot>