<?xml version="1.0" encoding="utf-8"?>
<robot
  name="petricor_platform">
  <link
    name="base_link">
    <inertial>
      <origin
        xyz="-4.87809042607272E-17 -2.29618809443724E-17 0.0879972764105627"
        rpy="0 0 0" />
      <mass
        value="5.87636303944341" />
      <inertia
        ixx="0.0760058697508826"
        ixy="1.4007807365218E-17"
        ixz="-4.91658511235952E-18"
        iyy="0.0517448560797098"
        iyz="-9.02756484418171E-19"
        izz="0.113814268741791" />
    </inertial>
    <visual>
      <origin
        xyz="0 0 0"
        rpy="0 0 0" />
      <geometry>
        <mesh
          filename="model://base_link.STL" />
      </geometry>
      <material
        name="">
        <color
          rgba="0.501960784313725 0.501960784313725 0.501960784313725 1" />
      </material>
    </visual>
    <collision>
      <origin
        xyz="0 0 0"
        rpy="0 0 0" />
      <geometry>
        <mesh
          filename="model://base_link.STL" />
      </geometry>
    </collision>
    <self_collide>0</self_collide>
  </link>
  <link
    name="wheel_FL">
    <inertial>
      <origin
        xyz="-0.015313 1.0317E-10 -6.0577E-11"
        rpy="0 0 0" />
      <mass
        value="0.2085" />
      <inertia
        ixx="0.00044907"
        ixy="-3.2704E-13"
        ixz="4.029E-13"
        iyy="0.00023777"
        iyz="-1.0058E-11"
        izz="0.00023777" />
    </inertial>
    <visual>
      <origin
        xyz="0 0 0"
        rpy="0 0 0" />
      <geometry>
        <mesh
          filename="model://wheel_FL.STL" />
      </geometry>
      <material
        name="">
        <color
          rgba="0.29804 0.29804 0.29804 1" />
      </material>
    </visual>
    <collision>
      <origin
        xyz="0 0 0"
        rpy="0 0 0" />
      <geometry>
        <mesh
          filename="model://wheel_FL.STL" />
      </geometry>
      <friction>
        <ode>
          <mu>5.0</mu>
          <mu2>5.0</mu2>
        </ode>
      </friction>
    </collision>
    <self_collide>0</self_collide>
  </link>
  <joint
    name="wheel_FL_rev"
    type="continuous">
    <origin
      xyz="0.10549 0.169 0.061"
      rpy="-0.33421 0 1.5708" />
    <parent
      link="base_link" />
    <child
      link="wheel_FL" />
    <axis
      xyz="-1 0 0" />
    <limit
      lower="0"
      upper="0"
      effort="1000000"
      velocity="1000" />
  </joint>
  <link
    name="wheel_FR">
    <inertial>
      <origin
        xyz="-0.015313 1.0317E-10 -6.0577E-11"
        rpy="0 0 0" />
      <mass
        value="0.2085" />
      <inertia
        ixx="0.00044907"
        ixy="-3.2704E-13"
        ixz="4.029E-13"
        iyy="0.00023777"
        iyz="1.788E-11"
        izz="0.00023777" />
    </inertial>
    <visual>
      <origin
        xyz="0 0 0"
        rpy="0 0 0" />
      <geometry>
        <mesh
          filename="model://wheel_FR.STL" />
      </geometry>
      <material
        name="">
        <color
          rgba="0.29804 0.29804 0.29804 1" />
      </material>
    </visual>
    <collision>
      <origin
        xyz="0 0 0"
        rpy="0 0 0" />
      <geometry>
        <mesh
          filename="model://wheel_FR.STL" />
      </geometry>
      <friction>
        <ode>
          <mu>5.0</mu>
          <mu2>5.0</mu2>
        </ode>
      </friction>
    </collision>
    <self_collide>0</self_collide>
  </link>
  <joint
    name="wheel_FR_rev"
    type="continuous">
    <origin
      xyz="0.10549 -0.169 0.061"
      rpy="-2.9492 0 -1.5708" />
    <parent
      link="base_link" />
    <child
      link="wheel_FR" />
    <axis
      xyz="-1 0 0" />
    <limit
      lower="0"
      upper="0"
      effort="1000000"
      velocity="1000" />
  </joint>
  <link
    name="wheel_BL">
    <inertial>
      <origin
        xyz="-0.015313 1.0317E-10 -6.0577E-11"
        rpy="0 0 0" />
      <mass
        value="0.2085" />
      <inertia
        ixx="0.00044907"
        ixy="-3.2704E-13"
        ixz="4.029E-13"
        iyy="0.00023777"
        iyz="-3.5686E-13"
        izz="0.00023777" />
    </inertial>
    <visual>
      <origin
        xyz="0 0 0"
        rpy="0 0 0" />
      <geometry>
        <mesh
          filename="model://wheel_BL.STL" />
      </geometry>
      <material
        name="">
        <color
          rgba="0.29804 0.29804 0.29804 1" />
      </material>
    </visual>
    <collision>
      <origin
        xyz="0 0 0"
        rpy="0 0 0" />
      <geometry>
        <mesh
          filename="model://wheel_BL.STL" />
      </geometry>
      <friction>
        <ode>
          <mu>5.0</mu>
          <mu2>5.0</mu2>
        </ode>
      </friction>
    </collision>
    <self_collide>0</self_collide>
  </link>
  <joint
    name="wheel_BL_rev"
    type="continuous">
    <origin
      xyz="-0.10549 0.169 0.061"
      rpy="0.82175 0 1.5708" />
    <parent
      link="base_link" />
    <child
      link="wheel_BL" />
    <axis
      xyz="-1 0 0" />
    <limit
      lower="0"
      upper="0"
      effort="1000000"
      velocity="1000" />
  </joint>
  <link
    name="wheel_BR">
    <inertial>
      <origin
        xyz="-0.015313 1.0317E-10 -6.0577E-11"
        rpy="0 0 0" />
      <mass
        value="0.2085" />
      <inertia
        ixx="0.00044907"
        ixy="-3.2704E-13"
        ixz="4.0289E-13"
        iyy="0.00023777"
        iyz="-8.8928E-12"
        izz="0.00023777" />
    </inertial>
    <visual>
      <origin
        xyz="0 0 0"
        rpy="0 0 0" />
      <geometry>
        <mesh
          filename="model://wheel_BR.STL" />
      </geometry>
      <material
        name="">
        <color
          rgba="0.29804 0.29804 0.29804 1" />
      </material>
    </visual>
    <collision>
      <origin
        xyz="0 0 0"
        rpy="0 0 0" />
      <geometry>
        <mesh
          filename="model://wheel_BR.STL" />
      </geometry>
      <friction>
        <ode>
          <mu>5.0</mu>
          <mu2>5.0</mu2>
        </ode>
      </friction>
    </collision>
    <self_collide>0</self_collide>
  </link>
  <joint
    name="wheel_BR_rev"
    type="continuous">
    <origin
      xyz="-0.10549 -0.169 0.061"
      rpy="0.53438 0 -1.5708" />
    <parent
      link="base_link" />
    <child
      link="wheel_BR" />
    <axis
      xyz="-1 0 0" />
    <limit
      lower="0"
      upper="0"
      effort="1000000"
      velocity="1000" />
  </joint>

  <link
    name="arm_base_link">
    <inertial>
      <origin
        xyz="-1.3323E-15 0.001416 0.028579"
        rpy="0 0 0" />
      <mass
        value="1.8167" />
      <inertia
        ixx="0.0092008"
        ixy="4.2883E-17"
        ixz="1.8255E-17"
        iyy="0.0050311"
        iyz="-4.9106E-05"
        izz="0.010824" />
    </inertial>
    <visual>
      <origin
        xyz="0 0 0"
        rpy="0 0 0" />
      <geometry>
        <mesh
          filename="model://arm_base_link.STL" />
      </geometry>
      <material
        name="">
        <color
          rgba="0.79216 0.81961 0.93333 1" />
      </material>
    </visual>
    <collision>
      <origin
        xyz="0 0 0"
        rpy="0 0 0" />
      <geometry>
        <mesh
          filename="model://arm_base_link.STL" />
      </geometry>
    </collision>
  </link>
  <joint
    name="arm_base_joint"
    type="revolute">
    <origin
      xyz="0 0 .17"
      rpy="0 0 1.57079" />
    <parent
      link="base_link" />
    <child
      link="arm_base_link" />
    <axis
      xyz="0 0 1" />
    <limit
      lower="0"
      upper="0"
      effort="0"
      velocity="0" />
  </joint>
  <link
    name="z_link">
    <inertial>
      <origin
        xyz="0.00052515 6.5815E-15 0.0054279"
        rpy="0 0 0" />
      <mass
        value="0.061611" />
      <inertia
        ixx="9.8218E-05"
        ixy="9.7777E-19"
        ixz="-4.4627E-07"
        iyy="1.1718E-05"
        iyz="-1.3574E-18"
        izz="0.00010811" />
    </inertial>
    <visual>
      <origin
        xyz="0 0 0"
        rpy="0 0 0" />
      <geometry>
        <mesh
          filename="model://z_link.STL" />
      </geometry>
      <material
        name="">
        <color
          rgba="0.79216 0.81961 0.93333 1" />
      </material>
    </visual>
    <collision>
      <origin
        xyz="0 0 0"
        rpy="0 0 0" />
      <geometry>
        <mesh
          filename="model://z_link.STL" />
      </geometry>
    </collision>
  </link>
  <joint
    name="z_prism"
    type="prismatic">
    <origin
      xyz="0.00097648 0 0.060561"
      rpy="0 0 0" />
    <parent
      link="arm_base_link" />
    <child
      link="z_link" />
    <axis
      xyz="0 0 1" />
    <limit
      lower="0.01"
      upper="0.27"
      effort="100"
      velocity="100" />
  </joint>
  <link
    name="right_shldr_link">
    <inertial>
      <origin
        xyz="0.052774 0.0011402 -0.0081027"
        rpy="0 0 0" />
      <mass
        value="0.025561" />
      <inertia
        ixx="1.2589E-06"
        ixy="1.5186E-06"
        ixz="2.2459E-07"
        iyy="3.4818E-05"
        iyz="4.9752E-09"
        izz="3.495E-05" />
    </inertial>
    <visual>
      <origin
        xyz="0 0 0"
        rpy="0 0 0" />
      <geometry>
        <mesh
          filename="model://right_shldr_link.STL" />
      </geometry>
      <material
        name="">
        <color
          rgba="0.96471 0.96471 0.95294 1" />
      </material>
    </visual>
    <collision>
      <origin
        xyz="0 0 0"
        rpy="0 0 0" />
      <geometry>
        <mesh
          filename="model://right_shldr_link.STL" />
      </geometry>
    </collision>
  </link>
  <joint
    name="right_shldr_rev"
    type="revolute">
    <origin
      xyz="0.017454 -0.055 0.028419"
      rpy="0 0 -0.61584" />
    <parent
      link="z_link" />
    <child
      link="right_shldr_link" />
    <axis
      xyz="0 0 -1" />
    <limit
      lower="-1.0"
      upper="1.0"
      effort="100"
      velocity="100" />
  </joint>
  <link
    name="right_elbw_link">
    <inertial>
      <origin
        xyz="0.10936 0.0025108 -0.015181"
        rpy="0 0 0" />
      <mass
        value="0.052137" />
      <inertia
        ixx="1.8081E-05"
        ixy="-6.9009E-06"
        ixz="2.9597E-05"
        iyy="0.00019669"
        iyz="2.6836E-06"
        izz="0.00018284" />
    </inertial>
    <visual>
      <origin
        xyz="0 0 0"
        rpy="0 0 0" />
      <geometry>
        <mesh
          filename="model://right_elbw_link.STL" />
      </geometry>
      <material
        name="">
        <color
          rgba="0.96471 0.96471 0.95294 1" />
      </material>
    </visual>
    <collision>
      <origin
        xyz="0 0 0"
        rpy="0 0 0" />
      <geometry>
        <mesh
          filename="model://right_elbw_link.STL" />
      </geometry>
    </collision>
  </link>
  <joint
    name="right_elbw_rev"
    type="revolute">
    <origin
      xyz="0.1 0 -0.018419"
      rpy="0 0 1.4276" />
    <parent
      link="right_shldr_link" />
    <child
      link="right_elbw_link" />
    <axis
      xyz="0 0 -1" />
    <limit
      lower="0.1"
      upper="1.75"
      effort="100"
      velocity="100" />
  </joint>
  <link
    name="EE_link">
    <inertial>
      <origin
        xyz="-7.1124E-15 4.8087E-15 0.030953"
        rpy="0 0 0" />
      <mass
        value="0.0062757" />
      <inertia
        ixx="1.5736E-06"
        ixy="7.714E-35"
        ixz="7.8936E-23"
        iyy="1.5736E-06"
        iyz="2.6001E-22"
        izz="1.1427E-07" />
    </inertial>
    <visual>
      <origin
        xyz="0 0 0"
        rpy="0 0 0" />
      <geometry>
        <mesh
          filename="model://EE_link.STL" />
      </geometry>
      <material
        name="">
        <color
          rgba="0.79216 0.81961 0.93333 1" />
      </material>
    </visual>
    <collision>
      <origin
        xyz="0 0 0"
        rpy="0 0 0" />
      <geometry>
        <mesh
          filename="model://EE_link.STL" />
      </geometry>
    </collision>
  </link>
  <joint
    name="EE_fixed"
    type="fixed">
    <origin
      xyz="0.1618 0 -0.07008"
      rpy="0 0 0" />
    <parent
      link="right_elbw_link" />
    <child
      link="EE_link" />
    <axis
      xyz="0 0 0" />
  </joint>
  <!-- <link
    name="left_shldr_link">
    <inertial>
      <origin
        xyz="0.052774 -0.0011402 -0.0081027"
        rpy="0 0 0" />
      <mass
        value="0.025561" />
      <inertia
        ixx="1.2589E-06"
        ixy="-1.5186E-06"
        ixz="2.2458E-07"
        iyy="3.4818E-05"
        iyz="-4.9734E-09"
        izz="3.495E-05" />
    </inertial>
    <visual>
      <origin
        xyz="0 0 0"
        rpy="0 0 0" />
      <geometry>
        <mesh
          filename="model://left_shldr_link.STL" />
      </geometry>
      <material
        name="">
        <color
          rgba="0.96471 0.96471 0.95294 1" />
      </material>
    </visual>
    <collision>
      <origin
        xyz="0 0 0"
        rpy="0 0 0" />
      <geometry>
        <mesh
          filename="model://left_shldr_link.STL" />
      </geometry>
    </collision>
  </link>
  <joint
    name="left_shldr_rev"
    type="revolute">
    <origin
      xyz="0.017454 0.055 0.028419"
      rpy="0 0 0.68233" />
    <parent
      link="z_link" />
    <child
      link="left_shldr_link" />
    <axis
      xyz="0 0 1" />
    <limit
      lower="-1.0"
      upper="1.0"
      effort="100"
      velocity="100" />
  </joint>
  <link
    name="left_elbw_link">
    <inertial>
      <origin
        xyz="0.077901 1.6504E-05 0.00080553"
        rpy="0 0 0" />
      <mass
        value="0.034948" />
      <inertia
        ixx="3.0317E-06"
        ixy="1.8828E-08"
        ixz="-1.1211E-05"
        iyy="0.0001049"
        iyz="6.3038E-08"
        izz="0.00010418" />
    </inertial>
    <visual>
      <origin
        xyz="0 0 0"
        rpy="0 0 0" />
      <geometry>
        <mesh
          filename="model://left_elbw_link.STL" />
      </geometry>
      <material
        name="">
        <color
          rgba="0.96471 0.96471 0.95294 1" />
      </material>
    </visual>
    <collision>
      <origin
        xyz="0 0 0"
        rpy="0 0 0" />
      <geometry>
        <mesh
          filename="model://left_elbw_link.STL" />
      </geometry>
    </collision>
  </link>
  <joint
    name="left_elbw_rev"
    type="revolute">
    <origin
      xyz="0.1 0 -0.018419"
      rpy="0 0 -1.4593" />
    <parent
      link="left_shldr_link" />
    <child
      link="left_elbw_link" />
    <axis
      xyz="0 0 1" />
    <limit
      lower="0.1"
      upper="1.75"
      effort="100"
      velocity="100" />
  </joint>
  <link
    name="dummy_link">
    <inertial>
      <origin
        xyz="-7.1193E-15 4.8087E-15 0.030953"
        rpy="0 0 0" />
      <mass
        value="0.0062757" />
      <inertia
        ixx="1.5736E-06"
        ixy="7.7136E-35"
        ixz="7.8936E-23"
        iyy="1.5736E-06"
        iyz="2.6001E-22"
        izz="1.1427E-07" />
    </inertial>
    <visual>
      <origin
        xyz="0 0 0"
        rpy="0 0 0" />
      <geometry>
        <mesh
          filename="model://dummy_link.STL" />
      </geometry>
      <material
        name="">
        <color
          rgba="0.79216 0.81961 0.93333 1" />
      </material>
    </visual>
    <collision>
      <origin
        xyz="0 0 0"
        rpy="0 0 0" />
      <geometry>
        <mesh
          filename="model://dummy_link.STL" />
      </geometry>
    </collision>
  </link>
  <joint
    name="dummy_rev"
    type="fixed">
    <origin
      xyz="0.1618 0 -0.07008"
      rpy="0 0 1.5887" />
    <parent
      link="left_elbw_link" />
    <child
      link="dummy_link" />
    <axis
      xyz="0 0 0" />
    <limit
      lower="0"
      upper="6.28"
      effort="0"
      velocity="0" />
  </joint> -->




   <ros2_control name="GazeboSystem" type="system">
    <hardware>
      <plugin>gazebo_ros2_control/GazeboSystem</plugin>
    </hardware>

    <joint name="wheel_FL_rev">
      <command_interface name="velocity">
        <param name="min">"-1000"</param>
        <param name="max">"1000"</param>
      </command_interface>
      <state_interface name="position"/>
      <state_interface name="velocity"/>
      <state_interface name="effort"/>
    </joint>

      <joint name="wheel_FR_rev">
      <command_interface name="velocity">
        <param name="min">"-1000"</param>
        <param name="max">"1000"</param>
      </command_interface>
      <state_interface name="position"/>
      <state_interface name="velocity"/>
      <state_interface name="effort"/>
    </joint>

      <joint name="wheel_BL_rev">
      <command_interface name="velocity">
        <param name="min">"-1000"</param>
        <param name="max">"1000"</param>
      </command_interface>
      <state_interface name="position"/>
      <state_interface name="velocity"/>
      <state_interface name="effort"/>
    </joint>

      <joint name="wheel_BR_rev">
      <command_interface name="velocity">
        <param name="min">"-1000"</param>
        <param name="max">"1000"</param>
      </command_interface>
      <state_interface name="position"/>
      <state_interface name="velocity"/>
      <state_interface name="effort"/>
    </joint>

    <joint name="right_shldr_rev">
      <command_interface name="position">
        <param name="min">"-1000"</param>
        <param name="max">"1000"</param>
      </command_interface>
      <state_interface name="position"/>
      <state_interface name="velocity"/>
      <state_interface name="effort"/>
    </joint>

    <joint name="right_elbw_rev">
      <command_interface name="position">
        <param name="min">"-1000"</param>
        <param name="max">"1000"</param>
      </command_interface>
      <state_interface name="position"/>
      <state_interface name="velocity"/>
      <state_interface name="effort"/>
    </joint>

  </ros2_control>

  <gazebo>
    <plugin name="gazebo_ros2_control" filename="libgazebo_ros2_control.so">
     <robot_param>robot_description</robot_param>
      <robot_param_node>robot_state_publisher</robot_param_node>
     <parameters>$(find platform_description)/config/combined.yaml</parameters>
    </plugin>

    <!-- <plugin name="gazebo_ros2_control" filename="libgazebo_ros2_control.so">
     <robot_param>robot_description</robot_param>
      <robot_param_node>robot_state_publisher</robot_param_node>
      <parameters>$(find simple_arm)/config/joint_names_Simple_arm.yaml</parameters>
    </plugin> -->

    <!-- 3D Pose publisher (emulate motion capture) -->
    <!-- See: https://github.com/ros-simulation/gazebo_ros_pkgs/wiki/ROS-2-Migration:-P3D -->
    <plugin name="gazebo_ros_p3d" filename="libgazebo_ros_p3d.so">
      <ros>
        <!-- Add namespace and remap the default topic -->
        <namespace>/petricor_platform</namespace>
        <argument>odom:=gazebo_odom</argument>
      </ros>

      <!-- Replace camelCase elements with camel_case ones -->
      <body_name>base_link</body_name>
      <frame_name>world</frame_name>
      <update_rate>50</update_rate> <!-- If set to 0, or don't include, will default to max possible -->
      <xyz_offset>0 0 0</xyz_offset>
      <rpy_offset>0 0 0</rpy_offset>
      <gaussian_noise>0.0001</gaussian_noise>

    </plugin>
  </gazebo>
</robot>