<?xml version="1.0" encoding="utf-8"?>
<!-- This URDF was automatically created by SolidWorks to URDF Exporter! Originally created by Stephen Brawner (brawner@gmail.com) 
     Commit Version: 1.6.0-1-g15f4949  Build Version: 1.6.7594.29634
     For more information, please see http://wiki.ros.org/sw_urdf_exporter -->
<robot
  name="petricor_platform">
  <link
    name="base_link">
    <inertial>
      <origin
        xyz="-4.87809042607272E-17 -2.29618809443724E-17 0.0879972764105627"
        rpy="0 0 0" />
      <mass
        value="5.87636303944341" />
      <inertia
        ixx="0.0760058697508826"
        ixy="1.4007807365218E-17"
        ixz="-4.91658511235952E-18"
        iyy="0.0517448560797098"
        iyz="-9.02756484418171E-19"
        izz="0.113814268741791" />
    </inertial>
    <visual>
      <origin
        xyz="0 0 0"
        rpy="0 0 0" />
      <geometry>
        <mesh
          filename="package://petricor_platform/meshes/base_link.STL" />
      </geometry>
      <material
        name="">
        <color
          rgba="0.501960784313725 0.501960784313725 0.501960784313725 1" />
      </material>
    </visual>
    <collision>
      <origin
        xyz="0 0 0"
        rpy="0 0 0" />
      <geometry>
        <mesh
          filename="package://petricor_platform/meshes/base_link.STL" />
      </geometry>
    </collision>
  </link>
  <link
    name="wheel_FL">
    <inertial>
      <origin
        xyz="-0.015313 1.0317E-10 -6.0577E-11"
        rpy="0 0 0" />
      <mass
        value="0.2085" />
      <inertia
        ixx="0.00044907"
        ixy="-3.2704E-13"
        ixz="4.029E-13"
        iyy="0.00023777"
        iyz="-1.0058E-11"
        izz="0.00023777" />
    </inertial>
    <visual>
      <origin
        xyz="0 0 0"
        rpy="0 0 0" />
      <geometry>
        <mesh
          filename="package://petricor_platform/meshes/wheel_FL.STL" />
      </geometry>
      <material
        name="">
        <color
          rgba="0.29804 0.29804 0.29804 1" />
      </material>
    </visual>
    <collision>
      <origin
        xyz="0 0 0"
        rpy="0 0 0" />
      <geometry>
        <mesh
          filename="package://petricor_platform/meshes/wheel_FL.STL" />
      </geometry>
    </collision>
  </link>
  <joint
    name="wheel_FL_rev"
    type="continuous">
    <origin
      xyz="0.10549 0.169 0.061"
      rpy="-0.33421 0 1.5708" />
    <parent
      link="base_link" />
    <child
      link="wheel_FL" />
    <axis
      xyz="-1 0 0" />
    <limit
      lower="0"
      upper="0"
      effort="1000000"
      velocity="1000" />
  </joint>
  <link
    name="wheel_FR">
    <inertial>
      <origin
        xyz="-0.015313 1.0317E-10 -6.0577E-11"
        rpy="0 0 0" />
      <mass
        value="0.2085" />
      <inertia
        ixx="0.00044907"
        ixy="-3.2704E-13"
        ixz="4.029E-13"
        iyy="0.00023777"
        iyz="1.788E-11"
        izz="0.00023777" />
    </inertial>
    <visual>
      <origin
        xyz="0 0 0"
        rpy="0 0 0" />
      <geometry>
        <mesh
          filename="package://petricor_platform/meshes/wheel_FR.STL" />
      </geometry>
      <material
        name="">
        <color
          rgba="0.29804 0.29804 0.29804 1" />
      </material>
    </visual>
    <collision>
      <origin
        xyz="0 0 0"
        rpy="0 0 0" />
      <geometry>
        <mesh
          filename="package://petricor_platform/meshes/wheel_FR.STL" />
      </geometry>
    </collision>
  </link>
  <joint
    name="wheel_FR_rev"
    type="continuous">
    <origin
      xyz="0.10549 -0.169 0.061"
      rpy="-2.9492 0 -1.5708" />
    <parent
      link="base_link" />
    <child
      link="wheel_FR" />
    <axis
      xyz="-1 0 0" />
    <limit
      lower="0"
      upper="0"
      effort="1000000"
      velocity="1000" />
  </joint>
  <link
    name="wheel_BL">
    <inertial>
      <origin
        xyz="-0.015313 1.0317E-10 -6.0577E-11"
        rpy="0 0 0" />
      <mass
        value="0.2085" />
      <inertia
        ixx="0.00044907"
        ixy="-3.2704E-13"
        ixz="4.029E-13"
        iyy="0.00023777"
        iyz="-3.5686E-13"
        izz="0.00023777" />
    </inertial>
    <visual>
      <origin
        xyz="0 0 0"
        rpy="0 0 0" />
      <geometry>
        <mesh
          filename="package://petricor_platform/meshes/wheel_BL.STL" />
      </geometry>
      <material
        name="">
        <color
          rgba="0.29804 0.29804 0.29804 1" />
      </material>
    </visual>
    <collision>
      <origin
        xyz="0 0 0"
        rpy="0 0 0" />
      <geometry>
        <mesh
          filename="package://petricor_platform/meshes/wheel_BL.STL" />
      </geometry>
    </collision>
  </link>
  <joint
    name="wheel_BL_rev"
    type="continuous">
    <origin
      xyz="-0.10549 0.169 0.061"
      rpy="0.82175 0 1.5708" />
    <parent
      link="base_link" />
    <child
      link="wheel_BL" />
    <axis
      xyz="-1 0 0" />
    <limit
      lower="0"
      upper="0"
      effort="1000000"
      velocity="1000" />
  </joint>
  <link
    name="wheel_BR">
    <inertial>
      <origin
        xyz="-0.015313 1.0317E-10 -6.0577E-11"
        rpy="0 0 0" />
      <mass
        value="0.2085" />
      <inertia
        ixx="0.00044907"
        ixy="-3.2704E-13"
        ixz="4.0289E-13"
        iyy="0.00023777"
        iyz="-8.8928E-12"
        izz="0.00023777" />
    </inertial>
    <visual>
      <origin
        xyz="0 0 0"
        rpy="0 0 0" />
      <geometry>
        <mesh
          filename="package://petricor_platform/meshes/wheel_BR.STL" />
      </geometry>
      <material
        name="">
        <color
          rgba="0.29804 0.29804 0.29804 1" />
      </material>
    </visual>
    <collision>
      <origin
        xyz="0 0 0"
        rpy="0 0 0" />
      <geometry>
        <mesh
          filename="package://petricor_platform/meshes/wheel_BR.STL" />
      </geometry>
    </collision>
  </link>
  <joint
    name="wheel_BR_rev"
    type="continuous">
    <origin
      xyz="-0.10549 -0.169 0.061"
      rpy="0.53438 0 -1.5708" />
    <parent
      link="base_link" />
    <child
      link="wheel_BR" />
    <axis
      xyz="-1 0 0" />
    <limit
      lower="0"
      upper="0"
      effort="1000000"
      velocity="1000" />
  </joint>
</robot>