<?xml version="1.0" encoding="utf-8"?>
<robot
  name="petricor_platform">
  <link
    name="base_link">
    <inertial>
      <origin
        xyz="-4.87809042607272E-17 -2.29618809443724E-17 0.0879972764105627"
        rpy="0 0 0" />
      <mass
        value="5.87636303944341" />
      <inertia
        ixx="0.0760058697508826"
        ixy="1.4007807365218E-17"
        ixz="-4.91658511235952E-18"
        iyy="0.0517448560797098"
        iyz="-9.02756484418171E-19"
        izz="0.113814268741791" />
    </inertial>
    <visual>
      <origin
        xyz="0 0 0"
        rpy="0 0 0" />
      <geometry>
        <mesh
          filename="model://base_link.STL" />
      </geometry>
      <material
        name="">
        <color
          rgba="0.501960784313725 0.501960784313725 0.501960784313725 1" />
      </material>
    </visual>
    <collision>
      <origin
        xyz="0 0 0"
        rpy="0 0 0" />
      <geometry>
        <mesh
          filename="model://base_link.STL" />
      </geometry>
    </collision>
    <self_collide>0</self_collide>
  </link>
  <link
    name="wheel_FL">
    <inertial>
      <origin
        xyz="-0.015313 1.0317E-10 -6.0577E-11"
        rpy="0 0 0" />
      <mass
        value="0.2085" />
      <inertia
        ixx="0.00044907"
        ixy="-3.2704E-13"
        ixz="4.029E-13"
        iyy="0.00023777"
        iyz="-1.0058E-11"
        izz="0.00023777" />
    </inertial>
    <visual>
      <origin
        xyz="0 0 0"
        rpy="0 0 0" />
      <geometry>
        <mesh
          filename="model://wheel_FL.STL" />
      </geometry>
      <material
        name="">
        <color
          rgba="0.29804 0.29804 0.29804 1" />
      </material>
    </visual>
    <collision>
      <origin
        xyz="0 0 0"
        rpy="0 0 0" />
      <geometry>
        <mesh
          filename="model://wheel_FL.STL" />
      </geometry>
      <friction>
        <ode>
          <mu>5.0</mu>
          <mu2>5.0</mu2>
        </ode>
      </friction>
    </collision>
    <self_collide>0</self_collide>
  </link>
  <joint
    name="wheel_FL_rev"
    type="continuous">
    <origin
      xyz="0.10549 0.169 0.061"
      rpy="-0.33421 0 1.5708" />
    <parent
      link="base_link" />
    <child
      link="wheel_FL" />
    <axis
      xyz="-1 0 0" />
    <limit
      lower="0"
      upper="0"
      effort="1000000"
      velocity="1000" />
  </joint>
  <link
    name="wheel_FR">
    <inertial>
      <origin
        xyz="-0.015313 1.0317E-10 -6.0577E-11"
        rpy="0 0 0" />
      <mass
        value="0.2085" />
      <inertia
        ixx="0.00044907"
        ixy="-3.2704E-13"
        ixz="4.029E-13"
        iyy="0.00023777"
        iyz="1.788E-11"
        izz="0.00023777" />
    </inertial>
    <visual>
      <origin
        xyz="0 0 0"
        rpy="0 0 0" />
      <geometry>
        <mesh
          filename="model://wheel_FR.STL" />
      </geometry>
      <material
        name="">
        <color
          rgba="0.29804 0.29804 0.29804 1" />
      </material>
    </visual>
    <collision>
      <origin
        xyz="0 0 0"
        rpy="0 0 0" />
      <geometry>
        <mesh
          filename="model://wheel_FR.STL" />
      </geometry>
      <friction>
        <ode>
          <mu>5.0</mu>
          <mu2>5.0</mu2>
        </ode>
      </friction>
    </collision>
    <self_collide>0</self_collide>
  </link>
  <joint
    name="wheel_FR_rev"
    type="continuous">
    <origin
      xyz="0.10549 -0.169 0.061"
      rpy="-2.9492 0 -1.5708" />
    <parent
      link="base_link" />
    <child
      link="wheel_FR" />
    <axis
      xyz="-1 0 0" />
    <limit
      lower="0"
      upper="0"
      effort="1000000"
      velocity="1000" />
  </joint>
  <link
    name="wheel_BL">
    <inertial>
      <origin
        xyz="-0.015313 1.0317E-10 -6.0577E-11"
        rpy="0 0 0" />
      <mass
        value="0.2085" />
      <inertia
        ixx="0.00044907"
        ixy="-3.2704E-13"
        ixz="4.029E-13"
        iyy="0.00023777"
        iyz="-3.5686E-13"
        izz="0.00023777" />
    </inertial>
    <visual>
      <origin
        xyz="0 0 0"
        rpy="0 0 0" />
      <geometry>
        <mesh
          filename="model://wheel_BL.STL" />
      </geometry>
      <material
        name="">
        <color
          rgba="0.29804 0.29804 0.29804 1" />
      </material>
    </visual>
    <collision>
      <origin
        xyz="0 0 0"
        rpy="0 0 0" />
      <geometry>
        <mesh
          filename="model://wheel_BL.STL" />
      </geometry>
      <friction>
        <ode>
          <mu>5.0</mu>
          <mu2>5.0</mu2>
        </ode>
      </friction>
    </collision>
    <self_collide>0</self_collide>
  </link>
  <joint
    name="wheel_BL_rev"
    type="continuous">
    <origin
      xyz="-0.10549 0.169 0.061"
      rpy="0.82175 0 1.5708" />
    <parent
      link="base_link" />
    <child
      link="wheel_BL" />
    <axis
      xyz="-1 0 0" />
    <limit
      lower="0"
      upper="0"
      effort="1000000"
      velocity="1000" />
  </joint>
  <link
    name="wheel_BR">
    <inertial>
      <origin
        xyz="-0.015313 1.0317E-10 -6.0577E-11"
        rpy="0 0 0" />
      <mass
        value="0.2085" />
      <inertia
        ixx="0.00044907"
        ixy="-3.2704E-13"
        ixz="4.0289E-13"
        iyy="0.00023777"
        iyz="-8.8928E-12"
        izz="0.00023777" />
    </inertial>
    <visual>
      <origin
        xyz="0 0 0"
        rpy="0 0 0" />
      <geometry>
        <mesh
          filename="model://wheel_BR.STL" />
      </geometry>
      <material
        name="">
        <color
          rgba="0.29804 0.29804 0.29804 1" />
      </material>
    </visual>
    <collision>
      <origin
        xyz="0 0 0"
        rpy="0 0 0" />
      <geometry>
        <mesh
          filename="model://wheel_BR.STL" />
      </geometry>
      <friction>
        <ode>
          <mu>5.0</mu>
          <mu2>5.0</mu2>
        </ode>
      </friction>
    </collision>
    <self_collide>0</self_collide>
  </link>
  <joint
    name="wheel_BR_rev"
    type="continuous">
    <origin
      xyz="-0.10549 -0.169 0.061"
      rpy="0.53438 0 -1.5708" />
    <parent
      link="base_link" />
    <child
      link="wheel_BR" />
    <axis
      xyz="-1 0 0" />
    <limit
      lower="0"
      upper="0"
      effort="1000000"
      velocity="1000" />
  </joint>  <ros2_control name="GazeboSystem" type="system">
    <hardware>
      <plugin>gazebo_ros2_control/GazeboSystem</plugin>
    </hardware>

    <joint name="wheel_FL_rev">
      <command_interface name="velocity">
        <param name="min">"-1000"</param>
        <param name="max">"1000"</param>
      </command_interface>
      <state_interface name="position"/>
      <state_interface name="velocity"/>
      <state_interface name="effort"/>
    </joint>

      <joint name="wheel_FR_rev">
      <command_interface name="velocity">
        <param name="min">"-1000"</param>
        <param name="max">"1000"</param>
      </command_interface>
      <state_interface name="position"/>
      <state_interface name="velocity"/>
      <state_interface name="effort"/>
    </joint>

      <joint name="wheel_BL_rev">
      <command_interface name="velocity">
        <param name="min">"-1000"</param>
        <param name="max">"1000"</param>
      </command_interface>
      <state_interface name="position"/>
      <state_interface name="velocity"/>
      <state_interface name="effort"/>
    </joint>

      <joint name="wheel_BR_rev">
      <command_interface name="velocity">
        <param name="min">"-1000"</param>
        <param name="max">"1000"</param>
      </command_interface>
      <state_interface name="position"/>
      <state_interface name="velocity"/>
      <state_interface name="effort"/>
    </joint>
  </ros2_control>

  <gazebo>
    <plugin name="gazebo_ros2_control" filename="libgazebo_ros2_control.so">
     <robot_param>robot_description</robot_param>
      <robot_param_node>robot_state_publisher</robot_param_node>
     <parameters>$(find platform_description)/config/joint_names_platform.yaml</parameters>
    </plugin>
    <!-- 3D Pose publisher (emulate motion capture) -->
    <!-- See: https://github.com/ros-simulation/gazebo_ros_pkgs/wiki/ROS-2-Migration:-P3D -->
    <plugin name="gazebo_ros_p3d" filename="libgazebo_ros_p3d.so">
      <ros>
        <!-- Add namespace and remap the default topic -->
        <namespace>/petricor_platform</namespace>
        <argument>odom:=gazebo_odom</argument>
      </ros>

      <!-- Replace camelCase elements with camel_case ones -->
      <body_name>base_link</body_name>
      <frame_name>world</frame_name>
      <update_rate>50</update_rate> <!-- If set to 0, or don't include, will default to max possible -->
      <xyz_offset>0 0 0</xyz_offset>
      <rpy_offset>0 0 0</rpy_offset>
      <gaussian_noise>0.0001</gaussian_noise>

    </plugin>
  </gazebo>
</robot>